<?xml version="1.0" encoding="utf-8"?>
<!-- This URDF was automatically created by SolidWorks to URDF Exporter! Originally created by Stephen Brawner (brawner@gmail.com) 
     Commit Version: 1.6.0-4-g7f85cfe  Build Version: 1.6.7995.38578
     For more information, please see http://wiki.ros.org/sw_urdf_exporter -->
<robot
  name="urdffp2">
  <link
    name="base">
    <inertial>
      <origin
        xyz="0.0127881966812722 0.113296131355283 0.0976093911317581"
        rpy="0 0 0" />
      <mass
        value="0.3" />
      <inertia
        ixx="0.00325212219571988"
        ixy="-0.000102809618600118"
        ixz="6.16552443350391E-05"
        iyy="0.00237760024152938"
        iyz="-0.000613324486301127"
        izz="0.00115371607461039" />
    </inertial>
    <visual>
      <origin
        xyz="0 0 0"
        rpy="0 0 0" />
      <geometry>
        <mesh
          filename="package://urdffp2/meshes/base.STL" />
      </geometry>
      <material
        name="">
        <color
          rgba="1 1 1 1" />
      </material>
    </visual>
    <collision>
      <origin
        xyz="0 0 0"
        rpy="0 0 0" />
      <geometry>
        <mesh
          filename="package://urdffp2/meshes/base.STL" />
      </geometry>
    </collision>
  </link>
  <link
    name="link1">
    <inertial>
      <origin
        xyz="0.0127881966812722 0.113296131355283 0.0976093911317581"
        rpy="0 0 0" />
      <mass
        value="0.3" />
      <inertia
        ixx="0.00325212219571988"
        ixy="-0.000102809618600118"
        ixz="6.16552443350391E-05"
        iyy="0.00237760024152938"
        iyz="-0.000613324486301127"
        izz="0.00115371607461039" />
    </inertial>
    <visual>
      <origin
        xyz="0 0 0"
        rpy="0 0 0" />
      <geometry>
        <mesh
          filename="package://urdffp2/meshes/link1.STL" />
      </geometry>
      <material
        name="">
        <color
          rgba="1 1 1 1" />
      </material>
    </visual>
    <collision>
      <origin
        xyz="0 0 0"
        rpy="0 0 0" />
      <geometry>
        <mesh
          filename="package://urdffp2/meshes/link1.STL" />
      </geometry>
    </collision>
  </link>
  <joint
    name="joint1"
    type="revolute">
    <origin
      xyz="0 0 0"
      rpy="0 0 0" />
    <parent
      link="base" />
    <child
      link="link1" />
    <axis
      xyz="0 0 1" />
    <limit
      lower="-3.14"
      upper="3.14"
      effort="0.833"
      velocity="5.23" />
  </joint>
  <link
    name="link2">
    <inertial>
      <origin
        xyz="0.012788 0.1133 0.097609"
        rpy="0 0 0" />
      <mass
        value="0.3" />
      <inertia
        ixx="0.0032521"
        ixy="-0.00010281"
        ixz="6.1655E-05"
        iyy="0.0023776"
        iyz="-0.00061332"
        izz="0.0011537" />
    </inertial>
    <visual>
      <origin
        xyz="0 0 0"
        rpy="0 0 0" />
      <geometry>
        <mesh
          filename="package://urdffp2/meshes/link2.STL" />
      </geometry>
      <material
        name="">
        <color
          rgba="0.79216 0.81961 0.93333 1" />
      </material>
    </visual>
    <collision>
      <origin
        xyz="0 0 0"
        rpy="0 0 0" />
      <geometry>
        <mesh
          filename="package://urdffp2/meshes/link2.STL" />
      </geometry>
    </collision>
  </link>
  <joint
    name="joint2"
    type="revolute">
    <origin
      xyz="0.015132 0 -0.0043844"
      rpy="1.5708 0 0" />
    <parent
      link="link1" />
    <child
      link="link2" />
    <axis
      xyz="0 0 -1" />
    <limit
      lower="-3.14"
      upper="3.14"
      effort="0.833"
      velocity="5.23" />
  </joint>
  <link
    name="link3">
    <inertial>
      <origin
        xyz="0.012788 0.1133 0.097609"
        rpy="0 0 0" />
      <mass
        value="0.3" />
      <inertia
        ixx="0.0032521"
        ixy="-0.00010281"
        ixz="6.1655E-05"
        iyy="0.0023776"
        iyz="-0.00061332"
        izz="0.0011537" />
    </inertial>
    <visual>
      <origin
        xyz="0 0 0"
        rpy="0 0 0" />
      <geometry>
        <mesh
          filename="package://urdffp2/meshes/link3.STL" />
      </geometry>
      <material
        name="">
        <color
          rgba="1 1 1 1" />
      </material>
    </visual>
    <collision>
      <origin
        xyz="0 0 0"
        rpy="0 0 0" />
      <geometry>
        <mesh
          filename="package://urdffp2/meshes/link3.STL" />
      </geometry>
    </collision>
  </link>
  <joint
    name="joint3"
    type="revolute">
    <origin
      xyz="0.07636 0.10521 0"
      rpy="0 0 0" />
    <parent
      link="link2" />
    <child
      link="link3" />
    <axis
      xyz="0 0 -1" />
    <limit
      lower="-3.14"
      upper="3.14"
      effort="0.833"
      velocity="5.23" />
  </joint>
  <link
    name="link4">
    <inertial>
      <origin
        xyz="0.012788 0.1133 0.097609"
        rpy="0 0 0" />
      <mass
        value="0.3" />
      <inertia
        ixx="0.0032521"
        ixy="-0.00010281"
        ixz="6.1655E-05"
        iyy="0.0023776"
        iyz="-0.00061332"
        izz="0.0011537" />
    </inertial>
    <visual>
      <origin
        xyz="0 0 0"
        rpy="0 0 0" />
      <geometry>
        <mesh
          filename="package://urdffp2/meshes/link4.STL" />
      </geometry>
      <material
        name="">
        <color
          rgba="1 1 1 1" />
      </material>
    </visual>
    <collision>
      <origin
        xyz="0 0 0"
        rpy="0 0 0" />
      <geometry>
        <mesh
          filename="package://urdffp2/meshes/link4.STL" />
      </geometry>
    </collision>
  </link>
  <joint
    name="joint4"
    type="revolute">
    <origin
      xyz="0.081624 -0.059241 0"
      rpy="0 0 0" />
    <parent
      link="link3" />
    <child
      link="link4" />
    <axis
      xyz="0 0 -1" />
    <limit
      lower="-3.14"
      upper="3.14"
      effort="0.833"
      velocity="5.23" />
  </joint>
  <link
    name="link5">
    <inertial>
      <origin
        xyz="0.012788 0.1133 0.097609"
        rpy="0 0 0" />
      <mass
        value="0.3" />
      <inertia
        ixx="0.0032521"
        ixy="-0.00010281"
        ixz="6.1655E-05"
        iyy="0.0023776"
        iyz="-0.00061332"
        izz="0.0011537" />
    </inertial>
    <visual>
      <origin
        xyz="0 0 0"
        rpy="0 0 0" />
      <geometry>
        <mesh
          filename="package://urdffp2/meshes/link5.STL" />
      </geometry>
      <material
        name="">
        <color
          rgba="0.79216 0.81961 0.93333 1" />
      </material>
    </visual>
    <collision>
      <origin
        xyz="0 0 0"
        rpy="0 0 0" />
      <geometry>
        <mesh
          filename="package://urdffp2/meshes/link5.STL" />
      </geometry>
    </collision>
  </link>
  <joint
    name="joint5"
    type="revolute">
    <origin
      xyz="0.042943 -0.052173 0.015825"
      rpy="1.5708 0 0" />
    <parent
      link="link4" />
    <child
      link="link5" />
    <axis
      xyz="0.58738 0 -0.80931" />
    <limit
      lower="-3.14"
      upper="3.14"
      effort="0.176"
      velocity="10.47" />
  </joint>
  <link
    name="link7">
    <inertial>
      <origin
        xyz="0.0127881966812722 0.113296131355283 0.0976093911317581"
        rpy="0 0 0" />
      <mass
        value="0.3" />
      <inertia
        ixx="0.00325212219571988"
        ixy="-0.000102809618600118"
        ixz="6.16552443350391E-05"
        iyy="0.00237760024152938"
        iyz="-0.000613324486301127"
        izz="0.00115371607461039" />
    </inertial>
    <visual>
      <origin
        xyz="0 0 0"
        rpy="0 0 0" />
      <geometry>
        <mesh
          filename="package://urdffp2/meshes/link7.STL" />
      </geometry>
      <material
        name="">
        <color
          rgba="1 1 1 1" />
      </material>
    </visual>
    <collision>
      <origin
        xyz="0 0 0"
        rpy="0 0 0" />
      <geometry>
        <mesh
          filename="package://urdffp2/meshes/link7.STL" />
      </geometry>
    </collision>
  </link>
  <joint
    name="joint7"
    type="fixed">
    <origin
      xyz="0.066828 -0.0125 0.048502"
      rpy="0 0 0" />
    <parent
      link="link5" />
    <child
      link="link7" />
    <axis
      xyz="0 0 0" />
  </joint>
  <link
    name="link6">
    <inertial>
      <origin
        xyz="0.0127881966812722 0.113296131355283 0.0976093911317581"
        rpy="0 0 0" />
      <mass
        value="0.3" />
      <inertia
        ixx="0.00325212219571988"
        ixy="-0.000102809618600118"
        ixz="6.16552443350391E-05"
        iyy="0.00237760024152938"
        iyz="-0.000613324486301127"
        izz="0.00115371607461039" />
    </inertial>
    <visual>
      <origin
        xyz="0 0 0"
        rpy="0 0 0" />
      <geometry>
        <mesh
          filename="package://urdffp2/meshes/link6.STL" />
      </geometry>
      <material
        name="">
        <color
          rgba="0.792156862745098 0.819607843137255 0.933333333333333 1" />
      </material>
    </visual>
    <collision>
      <origin
        xyz="0 0 0"
        rpy="0 0 0" />
      <geometry>
        <mesh
          filename="package://urdffp2/meshes/link6.STL" />
      </geometry>
    </collision>
  </link>
  <joint
    name="joint6"
    type="revolute">
    <origin
      xyz="0.043186 -0.052349 -0.011175"
      rpy="1.5708 0 0" />
    <parent
      link="link4" />
    <child
      link="link6" />
    <axis
      xyz="-0.58738 0 0.80931" />
    <limit
      lower="-3.14"
      upper="3.14"
      effort="0.176"
      velocity="10.47" />
  </joint>
  <link
    name="link8">
    <inertial>
      <origin
        xyz="0.0127881966812722 0.113296131355283 0.0976093911317581"
        rpy="0 0 0" />
      <mass
        value="0.3" />
      <inertia
        ixx="0.00325212219571988"
        ixy="-0.000102809618600118"
        ixz="6.16552443350391E-05"
        iyy="0.00237760024152938"
        iyz="-0.000613324486301127"
        izz="0.00115371607461039" />
    </inertial>
    <visual>
      <origin
        xyz="0 0 0"
        rpy="0 0 0" />
      <geometry>
        <mesh
          filename="package://urdffp2/meshes/link8.STL" />
      </geometry>
      <material
        name="">
        <color
          rgba="1 1 1 1" />
      </material>
    </visual>
    <collision>
      <origin
        xyz="0 0 0"
        rpy="0 0 0" />
      <geometry>
        <mesh
          filename="package://urdffp2/meshes/link8.STL" />
      </geometry>
    </collision>
  </link>
  <joint
    name="joint8"
    type="fixed">
    <origin
      xyz="0.067182 0.0058155 0.04876"
      rpy="0 0 0" />
    <parent
      link="link6" />
    <child
      link="link8" />
    <axis
      xyz="0 0 0" />
  </joint>
</robot>